File: ETO/sampleA+CResistivity/SA.dat
[Header]
;Copyright 2014, Quantum Design, Inc. All rights reserved.
FILEOPENTIME, 0.0, ,4/14/2017 6:05:32 PM
BYAPP, Electrical Transport Option, Release 1.1.1 Build 7
INFO, APPNAME, ETOption, Release 1.1.1 Build 7
TITLE, Electrical Transport Option (CAN)
STARTUPAXIS, X, 2, LINEAR, AUTO
STARTUPAXIS, Y1, 7, LINEAR, AUTO
STARTUPAXIS, Y2, 9, LINEAR, AUTO
STARTUPAXIS, Y3, 27, LINEAR, AUTO
STARTUPAXIS, Y4, 29, LINEAR, AUTO
TIMEMODE, SECONDS, RELATIVE
PLOT_APPEARANCE, ALL, HORZ_GRID_ON, VERT_GRID_ON,,AUTO_LINES
RECORDS, ALL_RECORDS
DATATYPE, COMMENT, 1
[Data]
Comment,Time Stamp (s),Temperature (K),Field (Oe),Sample Position (deg),Chamber Pressure (Torr),Resistance Ch1 (Ohms),Resistance Std. Dev. Ch1 (Ohms),Phase Angle Ch1 (deg),I-V Current Ch1 (mA),I-V Voltage Ch1 (V),Frequency Ch1 (Hz),Averaging Time Ch1 (s),AC Current Ch1 (mA),DC Current Ch1 (mA),Voltage Ampl Ch1 (V),In Phase Voltage Ampl Ch1 (V),Quadrature Voltage Ch1 (V),AC Voltage Ch1 (V),DC Voltage Ch1 (V),Current Ampl Ch1 (mA),In Phase Current Ch1 (mA),Quadrature Current Ch1 (mA),Gain Ch1,2nd Harmonic Ch1 (dB),3rd Harmonic Ch1 (dB),Resistance Ch2 (Ohms),Resistance Std. Dev. Ch2 (Ohms),Phase Angle Ch2 (deg),I-V Current Ch2 (mA),I-V Voltage Ch2 (V),Frequency Ch2 (Hz),Averaging Time Ch2 (s),AC Current Ch2 (mA),DC Current Ch2 (mA),Voltage Ampl Ch2 (V),In Phase Voltage Ampl Ch2 (V),Quadrature Voltage Ch2 (V),AC Voltage Ch2 (V),DC Voltage Ch2 (V),Current Ampl Ch2 (mA),In Phase Current Ch2 (mA),Quadrature Current Ch2 (mA),Gain Ch2,2nd Harmonic Ch2 (dB),3rd Harmonic Ch2 (dB),ETO Status Code,ETO Measurement Mode,ETO Channel 1,ETO Channel 2,ETO Channel 3,ETO Channel 4,ETO Channel 5,ETO Channel 6,ETO Channel 7,ETO Channel 8,ETO Channel 9,ETO Channel 10,ETO Channel 11,ETO Channel 12,ETO Channel 13,ETO Channel 14,ETO Channel 15,ETO Channel 16

,3701351039.23584,50.0563011169434,-0.188679158687592,,,,,,,,,,,,,,,,,,,,,,,0.560498,2.48237E-05,0.04313533,,,21.3623,0.98304,10,0,0.005604916,0.005604915,4.219681E-06,,,,,,300,-37.73151,-35.48455,402986368,0,,,,,,,,,,,,,,,,
,3701351040.90844,50.0548210144043,-0.193326443433762,,,,,,,,,,,,,,,,,,,,,,,0.5605037,2.390494E-05,0.04296792,,,21.3623,0.98304,10,0,0.005604973,0.005604972,4.203346E-06,,,,,,300,-37.73503,-35.47892,402986368,0,,,,,,,,,,,,,,,,
,3701351114.68935,50.0825042724609,-0.188679158687592,,,,,,,,,,,,,,,,,,,,,,,0.5605788,3.5692E-05,0.04314278,,,21.3623,0.98304,10,0,0.005605724,0.005605722,4.221017E-06,,,,,,300,-37.73236,-35.49316,402986368,0,,,,,,,,,,,,,,,,
,3701351275.21115,51.0513763427734,-0.193326443433762,,,,,,,,,,,,,,,,,,,,,,,0.5626835,2.325168E-05,0.04329458,,,21.3623,0.98304,10,0,0.00562677,0.005626769,4.251773E-06,,,,,,300,-37.67807,-36.34905,402986368,0,,,,,,,,,,,,,,,,
,3701351276.86913,51.0494155883789,-0.184031918644905,,,,,,,,,,,,,,,,,,,,,,,0.5627,2.232223E-05,0.0433854,,,21.3623,0.98304,10,0,0.005626936,0.005626934,4.260817E-06,,,,,,300,-37.67892,-36.34545,402986368,0,,,,,,,,,,,,,,,,
,3701351426.28597,52.048095703125,-0.19797371327877,,,,,,,,,,,,,,,,,,,,,,,0.5651974,2.519219E-05,0.04311346,,,21.3623,0.98304,10,0,0.005651909,0.005651908,4.252902E-06,,,,,,300,-37.60379,-37.23934,402986368,0,,,,,,,,,,,,,,,,
,3701351574.59558,53.0509338378906,-0.19797371327877,,,,,,,,,,,,,,,,,,,,,,,0.5680354,3.098909E-05,0.04336106,,,21.3623,0.98304,10,0,0.00568029,0.005680288,4.298804E-06,,,,,,300,-37.52299,-38.21011,402986368,0,,,,,,,,,,,,,,,,
,3701351576.23871,53.0484046936035,-0.20262099802494,,,,,,,,,,,,,,,,,,,,,,,0.5680227,2.873811E-05,0.04319644,,,21.3623,0.98304,10,0,0.005680162,0.005680161,4.282388E-06,,,,,,300,-37.53025,-38.20182,402986368,0,,,,,,,,,,,,,,,,
,3701351723.82952,54.049991607666,-0.184031918644905,,,,,,,,,,,,,,,,,,,,,,,0.5711924,1.567729E-05,0.04287111,,,21.3623,0.98304,10,0,0.005711859,0.005711858,4.273853E-06,,,,,,300,-37.44906,-39.30087,402986368,0,,,,,,,,,,,,,,,,
,3701351871.13106,55.051643371582,-0.170090109109879,,,,,,,,,,,,,,,,,,,,,,,0.5750263,3.001523E-05,0.04314507,,,21.3623,0.98304,10,0,0.005750198,0.005750196,4.330034E-06,,,,,,300,-37.32331,-40.55717,402986368,0,,,,,,,,,,,,,,,,
,3701351872.64727,55.0494651794434,-0.174737364053726,,,,,,,,,,,,,,,,,,,,,,,0.5750124,2.277968E-05,0.04300725,,,21.3623,0.98304,10,0,0.005750058,0.005750057,4.316098E-06,,,,,,300,-37.33507,-40.54866,402986368,0,,,,,,,,,,,,,,,,
,3701352018.94916,56.0531806945801,-0.179384633898735,,,,,,,,,,,,,,,,,,,,,,,0.5790842,2.683042E-05,0.04313416,,,21.3623,0.98304,10,0,0.005790776,0.005790774,4.359488E-06,,,,,,300,-37.22181,-42.04623,402986368,0,,,,,,,,,,,,,,,,
,3701352164.25188,57.0539207458496,-0.170090109109879,,,,,,,,,,,,,,,,,,,,,,,0.5833771,0.000164572,0.04321373,,,21.3623,0.98304,10,0,0.005833705,0.005833703,4.399908E-06,,,,,,300,-37.09031,-43.84931,402986368,0,,,,,,,,,,,,,,,,
,3701352165.91585,57.0522613525391,-0.170090109109879,,,,,,,,,,,,,,,,,,,,,,,0.5833014,2.269355E-05,0.04319879,,,21.3623,0.98304,10,0,0.005832948,0.005832946,4.397815E-06,,,,,,300,-37.09684,-43.8311,402986368,0,,,,,,,,,,,,,,,,
,3701352308.82642,58.0574111938477,-0.160795539617538,,,,,,,,,,,,,,,,,,,,,,,0.588151,2.854794E-05,0.04310266,,,21.3623,0.98304,10,0,0.005881443,0.005881441,4.424511E-06,,,,,,300,-36.95627,-45.96568,402986368,0,,,,,,,,,,,,,,,,
,3701352450.53916,59.0595664978027,-0.165442824363708,,,,,,,,,,,,,,,,,,,,,,,0.5931826,3.53917E-05,0.04278679,,,21.3623,0.98304,10,0,0.005931759,0.005931757,4.429662E-06,,,,,,300,-36.81317,-48.82578,402986368,0,,,,,,,,,,,,,,,,
,3701352452.14424,59.0569763183594,-0.174737364053726,,,,,,,,,,,,,,,,,,,,,,,0.5932643,1.443912E-05,0.04305051,,,21.3623,0.98304,10,0,0.005932576,0.005932574,4.457578E-06,,,,,,300,-36.80893,-48.82279,402986368,0,,,,,,,,,,,,,,,,
,3701352593.51672,60.0592575073242,-0.156148254871368,,,,,,,,,,,,,,,,,,,,,,,0.5988154,2.742407E-05,0.04272983,,,21.3623,0.98304,10,0,0.005988087,0.005988085,4.465772E-06,,,,,,300,-36.63402,-52.74263,402986368,0,,,,,,,,,,,,,,,,
,3701352732.98293,61.0635795593262,-0.165442824363708,,,,,,,,,,,,,,,,,,,,,,,0.6045692,3.290176E-05,0.04293938,,,21.3623,0.98304,10,0,0.006045623,0.006045621,4.530792E-06,,,,,,300,-36.46214,-59.58685,402986368,0,,,,,,,,,,,,,,,,
,3701352734.67584,61.060375213623,-0.151500999927521,,,,,,,,,,,,,,,,,,,,,,,0.6046035,3.786712E-05,0.04295494,,,21.3623,0.98304,10,0,0.006045966,0.006045965,4.532691E-06,,,,,,300,-36.45928,-59.62856,402986368,0,,,,,,,,,,,,,,,,
,3701352873.17303,62.0632057189941,-0.151500999927521,,,,,,,,,,,,,,,,,,,,,,,0.6104679,3.068208E-05,0.04272003,,,21.3623,0.98304,10,0,0.00610461,0.006104608,4.551629E-06,,,,,,300,-36.29319,-73.11205,402986368,0,,,,,,,,,,,,,,,,
,3701353011.20778,63.0629272460938,-0.146853730082512,,,,,,,,,,,,,,,,,,,,,,,0.6162239,2.49175E-05,0.04282366,,,21.3623,0.98304,10,0,0.006162168,0.006162167,4.60569E-06,,,,,,300,-36.11988,-56.48241,402986368,0,,,,,,,,,,,,,,,,
,3701353012.85322,63.0612449645996,-0.151500999927521,,,,,,,,,,,,,,,,,,,,,,,0.6161876,3.627568E-05,0.04295231,,,21.3623,0.98304,10,0,0.006161806,0.006161804,4.619254E-06,,,,,,300,-36.12344,-56.47186,402986368,0,,,,,,,,,,,,,,,,
,3701353148.31098,64.0668106079102,-0.151500999927521,,,,,,,,,,,,,,,,,,,,,,,0.6216348,2.736738E-05,0.04285892,,,21.3623,0.98304,10,0,0.006216277,0.006216275,4.649956E-06,,,,,,300,-35.96075,-51.22213,402986368,0,,,,,,,,,,,,,,,,
,3701353285.95712,65.0693511962891,-0.123617373406887,,,,,,,,,,,,,,,,,,,,,,,0.6267786,6.015023E-05,0.04295409,,,21.3623,0.98304,10,0,0.006267715,0.006267713,4.698845E-06,,,,,,300,-35.80946,-48.38535,402986368,0,,,,,,,,,,,,,,,,
,3701353287.61019,65.0657806396484,-0.142206445336342,,,,,,,,,,,,,,,,,,,,,,,0.6267042,4.060681E-05,0.04261187,,,21.3623,0.98304,10,0,0.00626697,0.006266968,4.660855E-06,,,,,,300,-35.8184,-48.39382,402986368,0,,,,,,,,,,,,,,,,
,3701353423.7795,66.0694351196289,-0.132911920547485,,,,,,,,,,,,,,,,,,,,,,,0.6314039,4.820478E-05,0.04282053,,,21.3623,0.98304,10,0,0.006313968,0.006313966,4.718802E-06,,,,,,300,-35.66549,-46.54671,402986368,0,,,,,,,,,,,,,,,,
,3701353561.04876,67.0693435668945,-0.137559175491333,,,,,,,,,,,,,,,,,,,,,,,0.6356658,0.0003648227,0.04288902,,,21.3623,0.98304,10,0,0.006356586,0.006356584,4.758251E-06,,,,,,300,-35.53979,-45.18615,402986368,0,,,,,,,,,,,,,,,,
,3701353562.7551,67.0669174194336,-0.137559175491333,,,,,,,,,,,,,,,,,,,,,,,0.6356292,0.0002258408,0.04278148,,,21.3623,0.98304,10,0,0.006356219,0.006356217,4.746046E-06,,,,,,300,-35.54065,-45.18798,402986368,0,,,,,,,,,,,,,,,,
,3701353698.22219,68.0731582641602,-0.132911920547485,,,,,,,,,,,,,,,,,,,,,,,0.6394832,3.602418E-05,0.04292388,,,21.3623,0.98304,10,0,0.006394759,0.006394757,4.790717E-06,,,,,,300,-35.42378,-44.18956,402986368,0,,,,,,,,,,,,,,,,
,3701353834.07009,69.0720596313477,-0.132911920547485,,,,,,,,,,,,,,,,,,,,,,,0.6428617,0.0002441732,0.04302242,,,21.3623,0.98304,10,0,0.006428544,0.006428542,4.827083E-06,,,,,,300,-35.32788,-43.20086,402986368,0,,,,,,,,,,,,,,,,
,3701353835.71607,69.0697860717773,-0.142206445336342,,,,,,,,,,,,,,,,,,,,,,,0.6428632,0.000282284,0.04288723,,,21.3623,0.98304,10,0,0.006428559,0.006428557,4.811926E-06,,,,,,300,-35.3203,-43.19621,402986368,0,,,,,,,,,,,,,,,,
,3701353970.77999,70.0732574462891,-0.128264650702477,,,,,,,,,,,,,,,,,,,,,,,0.6458066,2.61374E-05,0.0428052,,,21.3623,0.98304,10,0,0.006457993,0.006457991,4.824712E-06,,,,,,300,-35.23912,-42.58897,402986368,0,,,,,,,,,,,,,,,,
,3701354105.40229,71.0762939453125,-0.132911920547485,,,,,,,,,,,,,,,,,,,,,,,0.6488294,5.234324E-05,0.04298924,,,21.3623,0.98304,10,0,0.00648822,0.006488218,4.868135E-06,,,,,,300,-35.15891,-42.07042,402986368,0,,,,,,,,,,,,,,,,
,3701354107.06293,71.072395324707,-0.132911920547485,,,,,,,,,,,,,,,,,,,,,,,0.6487791,2.794554E-05,0.04282411,,,21.3623,0.98304,10,0,0.006487717,0.006487716,4.849061E-06,,,,,,300,-35.15606,-42.08868,402986368,0,,,,,,,,,,,,,,,,
,3701354242.28598,72.0735778808594,-0.128264650702477,,,,,,,,,,,,,,,,,,,,,,,0.6521091,0.0001662855,0.04286216,,,21.3623,0.98304,10,0,0.006521017,0.006521015,4.87828E-06,,,,,,300,-35.07175,-41.79817,402986368,0,,,,,,,,,,,,,,,,
,3701354377.95841,73.0724563598633,-0.123617373406887,,,,,,,,,,,,,,,,,,,,,,,0.656333,0.0002173378,0.04265339,,,21.3623,0.98304,10,0,0.006563256,0.006563254,4.885964E-06,,,,,,300,-34.95258,-41.70857,402986368,0,,,,,,,,,,,,,,,,
,3701354379.57697,73.0696334838867,-0.137559175491333,,,,,,,,,,,,,,,,,,,,,,,0.6562945,0.0003700409,0.04286737,,,21.3623,0.98304,10,0,0.00656287,0.006562868,4.910186E-06,,,,,,300,-34.94811,-41.702,402986368,0,,,,,,,,,,,,,,,,
,3701354513.69586,74.0765838623047,-0.128264650702477,,,,,,,,,,,,,,,,,,,,,,,0.661828,0.000297932,0.04248637,,,21.3623,0.98304,10,0,0.006618205,0.006618203,4.907577E-06,,,,,,300,-34.83184,-41.39766,402986368,0,,,,,,,,,,,,,,,,
,3701354648.18472,75.0776901245117,-0.128264650702477,,,,,,,,,,,,,,,,,,,,,,,0.6682002,2.595721E-05,0.04216507,,,21.3623,0.98304,10,0,0.006681926,0.006681924,4.917358E-06,,,,,,300,-34.69886,-40.86288,402986368,0,,,,,,,,,,,,,,,,
,3701354649.84752,75.0752868652344,-0.123617373406887,,,,,,,,,,,,,,,,,,,,,,,0.6682402,3.896772E-05,0.04277532,,,21.3623,0.98304,10,0,0.006682327,0.006682325,4.988825E-06,,,,,,300,-34.69766,-40.87336,402986368,0,,,,,,,,,,,,,,,,
,3701354783.93084,76.0755920410156,-0.132911920547485,,,,,,,,,,,,,,,,,,,,,,,0.6932195,0.0001102481,0.04228135,,,21.3623,0.98304,10,0,0.006932116,0.006932114,5.115546E-06,,,,,,300,-34.54013,-43.12791,402986368,0,,,,,,,,,,,,,,,,
,3701354916.793,77.0813217163086,-0.128264650702477,,,,,,,,,,,,,,,,,,,,,,,2.154184,0.002204942,-0.01889564,,,21.3623,0.98304,10,0,0.02154159,0.02154159,-7.104225E-06,,,,,,100,-43.91217,-25.37617,151328128,0,,,,,,,,,,,,,,,,
,3701354918.42498,77.0771331787109,-0.123617373406887,,,,,,,,,,,,,,,,,,,,,,,2.141513,0.001942436,-0.01869347,,,21.3623,0.98304,10,0,0.02141489,0.02141488,-6.986877E-06,,,,,,100,-43.92919,-25.36662,151328128,0,,,,,,,,,,,,,,,,
,3701355051.13621,78.0804290771484,-0.128264650702477,,,,,,,,,,,,,,,,,,,,,,,5.576148,0.005708479,-0.03557144,,,21.3623,0.98304,10,0,0.05576084,0.05576083,-3.461849E-05,,,,,,30,-48.23811,-38.2981,147133824,0,,,,,,,,,,,,,,,,
,3701355183.12879,79.0819625854492,-0.123617373406887,,,,,,,,,,,,,,,,,,,,,,,8.48516,0.0006735156,-0.009876352,,,21.3623,0.98304,10,0,0.08485061,0.08485061,-1.462611E-05,,,,,,10,-50.08039,-48.98592,142939520,0,,,,,,,,,,,,,,,,
,3701355184.7067,79.0786819458008,-0.128264650702477,,,,,,,,,,,,,,,,,,,,,,,8.480313,0.0007122419,-0.009936,,,21.3623,0.98304,10,0,0.08480214,0.08480214,-1.470604E-05,,,,,,10,-50.09324,-49.00986,142939520,0,,,,,,,,,,,,,,,,
,3701355315.71604,80.0823669433594,-0.123617373406887,,,,,,,,,,,,,,,,,,,,,,,9.176275,0.000241549,-0.004287011,,,21.3623,0.98304,10,0,0.09176168,0.09176168,-6.865833E-06,,,,,,10,-49.06513,-47.09487,142939520,0,,,,,,,,,,,,,,,,
,3701355446.06143,81.0844802856445,-0.137559175491333,,,,,,,,,,,,,,,,,,,,,,,9.542576,0.0001694646,-0.003031291,,,21.3623,0.98304,10,0,0.09542464,0.09542464,-5.048538E-06,,,,,,10,-48.70611,-46.50152,142939520,0,,,,,,,,,,,,,,,,
,3701355447.76551,81.08154296875,-0.137559175491333,,,,,,,,,,,,,,,,,,,,,,,9.541471,0.0001868378,-0.003064389,,,21.3623,0.98304,10,0,0.0954136,0.0954136,-5.103069E-06,,,,,,10,-48.70627,-46.50166,142939520,0,,,,,,,,,,,,,,,,
,3701355578.67897,82.0834808349609,-0.128264650702477,,,,,,,,,,,,,,,,,,,,,,,9.798545,0.00019117,-0.002633925,,,21.3623,0.98304,10,0,0.09798431,0.09798431,-4.504403E-06,,,,,,10,-48.54157,-46.20433,142939520,0,,,,,,,,,,,,,,,,
,3701355708.65236,83.0870208740234,-0.132911920547485,,,,,,,,,,,,,,,,,,,,,,,9.999532,8.041065E-05,-0.002297242,,,21.3623,0.98304,10,0,0.09999415,0.09999415,-4.00921E-06,,,,,,10,-48.44286,-46.03437,142939520,0,,,,,,,,,,,,,,,,
,3701355710.31761,83.0839691162109,-0.132911920547485,,,,,,,,,,,,,,,,,,,,,,,9.998749,0.0001318609,-0.002226851,,,21.3623,0.98304,10,0,0.09998631,0.09998631,-3.886056E-06,,,,,,10,-48.44328,-46.03882,142939520,0,,,,,,,,,,,,,,,,
,3701355839.51503,84.0858688354492,-0.132911920547485,,,,,,,,,,,,,,,,,,,,,,,10.16564,0.0001101318,-0.002049053,,,21.3623,0.98304,10,0,0.1016552,0.1016552,-3.635467E-06,,,,,,10,-48.39011,-45.93668,142939520,0,,,,,,,,,,,,,,,,
,3701355967.4626,85.0907211303711,-0.132911920547485,,,,,,,,,,,,,,,,,,,,,,,10.30975,8.961962E-05,-0.001902058,,,21.3623,0.98304,10,0,0.1030963,0.1030963,-3.422506E-06,,,,,,10,-48.35413,-45.88411,142939520,0,,,,,,,,,,,,,,,,
,3701355969.29258,85.0871887207031,-0.137559175491333,,,,,,,,,,,,,,,,,,,,,,,10.30924,0.0001220698,-0.001921951,,,21.3623,0.98304,10,0,0.1030912,0.1030912,-3.458128E-06,,,,,,10,-48.3513,-45.88442,142939520,0,,,,,,,,,,,,,,,,
,3701356095.12036,86.0938186645508,-0.132911920547485,,,,,,,,,,,,,,,,,,,,,,,10.43628,0.0001119128,-0.001922482,,,21.3623,0.98304,10,0,0.1043616,0.1043616,-3.50171E-06,,,,,,10,-48.35363,-45.86514,142939520,0,,,,,,,,,,,,,,,,
,3701356218.28481,87.0990753173828,-0.137559175491333,,,,,,,,,,,,,,,,,,,,,,,10.55061,0.0001274742,-0.001741159,,,21.3623,0.98304,10,0,0.1055049,0.1055049,-3.206184E-06,,,,,,10,-48.36459,-45.86771,142939520,0,,,,,,,,,,,,,,,,
,3701356220.12968,87.0953750610352,-0.128264650702477,,,,,,,,,,,,,,,,,,,,,,,10.55007,5.77864E-05,-0.001713741,,,21.3623,0.98304,10,0,0.1054995,0.1054995,-3.155534E-06,,,,,,10,-48.36388,-45.8665,142939520,0,,,,,,,,,,,,,,,,
,3701356293.84389,88.3037414550781,-0.132911920547485,,,,,,,,,,,,,,,,,,,,,,,10.67351,9.691599E-05,-0.001720176,,,21.3623,0.98304,10,0,0.1067339,0.1067339,-3.204442E-06,,,,,,10,-48.3989,-45.89594,142939520,0,,,,,,,,,,,,,,,,
,3701356413.73854,89.106086730957,-0.137559175491333,,,,,,,,,,,,,,,,,,,,,,,10.74908,0.0001133963,-0.001586415,,,21.3623,0.98304,10,0,0.1074895,0.1074895,-2.976187E-06,,,,,,10,-48.42924,-45.92452,142939520,0,,,,,,,,,,,,,,,,
,3701356415.37564,89.1022644042969,-0.128264650702477,,,,,,,,,,,,,,,,,,,,,,,10.74857,0.0001002096,-0.001610224,,,21.3623,0.98304,10,0,0.1074844,0.1074844,-3.020712E-06,,,,,,10,-48.43068,-45.92569,142939520,0,,,,,,,,,,,,,,,,
,3701356488.38272,90.3042755126953,-0.118970096111298,,,,,,,,,,,,,,,,,,,,,,,10.85265,7.333075E-05,-0.001653813,,,21.3623,0.98304,10,0,0.1085252,0.1085252,-3.132524E-06,,,,,,10,-48.48491,-45.98283,142939520,0,,,,,,,,,,,,,,,,
,3701356585.94694,91.1775131225586,-0.123617373406887,,,,,,,,,,,,,,,,,,,,,,,10.92519,0.0001492823,-0.001500636,,,21.3623,0.98304,10,0,0.1092506,0.1092506,-2.861386E-06,,,,,,10,-48.53001,-46.0331,142939520,0,,,,,,,,,,,,,,,,
,3701356587.59462,91.1709060668945,-0.128264650702477,,,,,,,,,,,,,,,,,,,,,,,10.92459,0.0001154437,-0.001577378,,,21.3623,0.98304,10,0,0.1092446,0.1092446,-3.007552E-06,,,,,,10,-48.52968,-46.03609,142939520,0,,,,,,,,,,,,,,,,
,3701356660.25555,92.3052215576172,-0.137559175491333,,,,,,,,,,,,,,,,,,,,,,,11.01019,0.0001221267,-0.001465747,,,21.3623,0.98304,10,0,0.1101006,0.1101006,-2.816606E-06,,,,,,10,-48.59599,-46.10947,142939520,0,,,,,,,,,,,,,,,,
,3701356734.87471,93.2962951660156,-0.128264650702477,,,,,,,,,,,,,,,,,,,,,,,11.08207,9.883232E-05,-0.001459033,,,21.3623,0.98304,10,0,0.1108194,0.1108194,-2.822007E-06,,,,,,10,-48.68197,-46.20124,142939520,0,,,,,,,,,,,,,,,,
,3701356736.51879,93.2861557006836,-0.123617373406887,,,,,,,,,,,,,,,,,,,,,,,11.08142,9.629648E-05,-0.001472126,,,21.3623,0.98304,10,0,0.110813,0.110813,-2.847167E-06,,,,,,10,-48.68046,-46.19894,142939520,0,,,,,,,,,,,,,,,,
,3701356811.29673,94.2937927246094,-0.128264650702477,,,,,,,,,,,,,,,,,,,,,,,11.15065,8.290057E-05,-0.00146821,,,21.3623,0.98304,10,0,0.1115052,0.1115052,-2.857331E-06,,,,,,10,-48.76455,-46.28298,142939520,0,,,,,,,,,,,,,,,,
,3701356885.65358,95.2969055175781,-0.132911920547485,,,,,,,,,,,,,,,,,,,,,,,11.21627,0.0001183456,-0.001442974,,,21.3623,0.98304,10,0,0.1121613,0.1121613,-2.824743E-06,,,,,,10,-48.83478,-46.36944,142939520,0,,,,,,,,,,,,,,,,
,3701356887.39807,95.2837677001953,-0.137559175491333,,,,,,,,,,,,,,,,,,,,,,,11.21568,0.0001599927,-0.001440092,,,21.3623,0.98304,10,0,0.1121555,0.1121555,-2.818955E-06,,,,,,10,-48.83723,-46.37026,142939520,0,,,,,,,,,,,,,,,,
,3701356960.83387,96.299430847168,-0.128264650702477,,,,,,,,,,,,,,,,,,,,,,,11.27929,6.881655E-05,-0.001388501,,,21.3623,0.98304,10,0,0.1127916,0.1127916,-2.733382E-06,,,,,,10,-48.91764,-46.46395,142939520,0,,,,,,,,,,,,,,,,
,3701357035.16966,97.2951126098633,-0.123617373406887,,,,,,,,,,,,,,,,,,,,,,,11.33934,8.994291E-05,-0.00138769,,,21.3623,0.98304,10,0,0.1133921,0.1133921,-2.746328E-06,,,,,,10,-48.99696,-46.55891,142939520,0,,,,,,,,,,,,,,,,
,3701357036.8378,97.2850494384766,-0.128264650702477,,,,,,,,,,,,,,,,,,,,,,,11.3389,7.184775E-05,-0.001453521,,,21.3623,0.98304,10,0,0.1133877,0.1133877,-2.876502E-06,,,,,,10,-48.99822,-46.55955,142939520,0,,,,,,,,,,,,,,,,
,3701357111.54785,98.2911987304688,-0.123617373406887,,,,,,,,,,,,,,,,,,,,,,,11.3974,7.80058E-05,-0.00131201,,,21.3623,0.98304,10,0,0.1139727,0.1139727,-2.60985E-06,,,,,,10,-49.08312,-46.66157,142939520,0,,,,,,,,,,,,,,,,
,3701357186.80835,99.2939300537109,-0.137559175491333,,,,,,,,,,,,,,,,,,,,,,,11.45405,8.494339E-05,-0.001372386,,,21.3623,0.98304,10,0,0.1145391,0.1145391,-2.743517E-06,,,,,,10,-49.17832,-46.76414,142939520,0,,,,,,,,,,,,,,,,
,3701357188.30771,99.2840347290039,-0.123617373406887,,,,,,,,,,,,,,,,,,,,,,,11.45366,0.000118764,-0.001379185,,,21.3623,0.98304,10,0,0.1145352,0.1145352,-2.757013E-06,,,,,,10,-49.18137,-46.76188,142939520,0,,,,,,,,,,,,,,,,
,3701357261.1112,100.303207397461,-0.132911920547485,,,,,,,,,,,,,,,,,,,,,,,11.50871,6.462808E-05,-0.001451003,,,21.3623,0.98304,10,0,0.1150857,0.1150857,-2.914521E-06,,,,,,10,-49.27225,-46.87122,142939520,0,,,,,,,,,,,,,,,,
,3701357335.86431,101.293663024902,-0.137559175491333,,,,,,,,,,,,,,,,,,,,,,,11.5618,7.523961E-05,-0.00133042,,,21.3623,0.98304,10,0,0.1156167,0.1156167,-2.684643E-06,,,,,,10,-49.35775,-46.98057,142939520,0,,,,,,,,,,,,,,,,
,3701357337.48099,101.283279418945,-0.146853730082512,,,,,,,,,,,,,,,,,,,,,,,11.5615,8.043333E-05,-0.001350815,,,21.3623,0.98304,10,0,0.1156137,0.1156137,-2.725729E-06,,,,,,10,-49.3616,-46.97878,142939520,0,,,,,,,,,,,,,,,,
,3701357412.13939,102.28751373291,-0.142206445336342,,,,,,,,,,,,,,,,,,,,,,,11.61342,9.028606E-05,-0.001383717,,,21.3623,0.98304,10,0,0.1161328,0.1161328,-2.804657E-06,,,,,,10,-49.43849,-47.09952,142939520,0,,,,,,,,,,,,,,,,
,3701357486.86031,103.29337310791,-0.137559175491333,,,,,,,,,,,,,,,,,,,,,,,11.66403,6.723297E-05,-0.001401819,,,21.3623,0.98304,10,0,0.1166389,0.1166389,-2.853728E-06,,,,,,10,-49.52839,-47.21436,142939520,0,,,,,,,,,,,,,,,,
,3701357488.45608,103.283279418945,-0.137559175491333,,,,,,,,,,,,,,,,,,,,,,,11.66375,4.508959E-05,-0.001347598,,,21.3623,0.98304,10,0,0.1166361,0.1166361,-2.743284E-06,,,,,,10,-49.52308,-47.21423,142939520,0,,,,,,,,,,,,,,,,
,3701357563.61495,104.287696838379,-0.128264650702477,,,,,,,,,,,,,,,,,,,,,,,11.71369,6.840868E-05,-0.001323481,,,21.3623,0.98304,10,0,0.1171355,0.1171355,-2.705725E-06,,,,,,10,-49.62487,-47.32996,142939520,0,,,,,,,,,,,,,,,,
,3701357638.95293,105.293190002441,-0.137559175491333,,,,,,,,,,,,,,,,,,,,,,,11.76156,5.480076E-05,-0.001320544,,,21.3623,0.98304,10,0,0.1176142,0.1176142,-2.710754E-06,,,,,,10,-49.72567,-47.45082,142939520,0,,,,,,,,,,,,,,,,
,3701357640.6538,105.279487609863,-0.137559175491333,,,,,,,,,,,,,,,,,,,,,,,11.76136,7.769304E-05,-0.001387914,,,21.3623,0.98304,10,0,0.1176122,0.1176122,-2.848998E-06,,,,,,10,-49.72239,-47.44805,142939520,0,,,,,,,,,,,,,,,,
,3701357716.20556,106.282485961914,-0.132911920547485,,,,,,,,,,,,,,,,,,,,,,,11.80811,7.538027E-05,-0.001389257,,,21.3623,0.98304,10,0,0.1180797,0.1180797,-2.863092E-06,,,,,,10,-49.82609,-47.56696,142939520,0,,,,,,,,,,,,,,,,
,3701357791.50381,107.288795471191,-0.132911920547485,,,,,,,,,,,,,,,,,,,,,,,11.85417,5.880715E-05,-0.001288929,,,21.3623,0.98304,10,0,0.1185403,0.1185403,-2.666689E-06,,,,,,10,-49.92804,-47.68848,142939520,0,,,,,,,,,,,,,,,,
,3701357793.27361,107.279434204102,-0.132911920547485,,,,,,,,,,,,,,,,,,,,,,,11.8539,6.301474E-05,-0.001308569,,,21.3623,0.98304,10,0,0.1185377,0.1185377,-2.707263E-06,,,,,,10,-49.92605,-47.68592,142939520,0,,,,,,,,,,,,,,,,
,3701357867.85395,108.288887023926,-0.123617373406887,,,,,,,,,,,,,,,,,,,,,,,11.89879,6.272617E-05,-0.001285935,,,21.3623,0.98304,10,0,0.1189865,0.1189865,-2.670511E-06,,,,,,10,-50.01931,-47.8109,142939520,0,,,,,,,,,,,,,,,,
,3701357942.38255,109.295951843262,-0.132911920547485,,,,,,,,,,,,,,,,,,,,,,,11.9431,5.315313E-05,-0.001414884,,,21.3623,0.98304,10,0,0.1194296,0.1194296,-2.949242E-06,,,,,,10,-50.12179,-47.93532,142939520,0,,,,,,,,,,,,,,,,
,3701357944.23131,109.283706665039,-0.128264650702477,,,,,,,,,,,,,,,,,,,,,,,11.94286,7.119581E-05,-0.001411415,,,21.3623,0.98304,10,0,0.1194272,0.1194272,-2.941951E-06,,,,,,10,-50.12178,-47.93581,142939520,0,,,,,,,,,,,,,,,,
,3701358018.56812,110.290245056152,-0.128264650702477,,,,,,,,,,,,,,,,,,,,,,,11.98631,4.793473E-05,-0.001275891,,,21.3623,0.98304,10,0,0.1198616,0.1198616,-2.66914E-06,,,,,,10,-50.22597,-48.05981,142939520,0,,,,,,,,,,,,,,,,
,3701358093.59417,111.292091369629,-0.132911920547485,,,,,,,,,,,,,,,,,,,,,,,12.02908,7.033452E-05,-0.001295951,,,21.3623,0.98304,10,0,0.1202894,0.1202894,-2.72078E-06,,,,,,10,-50.33558,-48.18279,142939520,0,,,,,,,,,,,,,,,,
,3701358095.25634,111.28343963623,-0.128264650702477,,,,,,,,,,,,,,,,,,,,,,,12.02882,6.094706E-05,-0.001334253,,,21.3623,0.98304,10,0,0.1202868,0.1202868,-2.80113E-06,,,,,,10,-50.33389,-48.18316,142939520,0,,,,,,,,,,,,,,,,
,3701358170.62202,112.283065795898,-0.123617373406887,,,,,,,,,,,,,,,,,,,,,,,12.07103,6.143217E-05,-0.001341191,,,21.3623,0.98304,10,0,0.1207089,0.1207089,-2.825577E-06,,,,,,10,-50.44634,-48.30784,142939520,0,,,,,,,,,,,,,,,,
,3701358245.6384,113.291084289551,-0.123617373406887,,,,,,,,,,,,,,,,,,,,,,,12.11251,0.0001090615,-0.001274716,,,21.3623,0.98304,10,0,0.1211237,0.1211237,-2.69476E-06,,,,,,10,-50.56236,-48.43519,142939520,0,,,,,,,,,,,,,,,,
,3701358247.35829,113.282112121582,-0.123617373406887,,,,,,,,,,,,,,,,,,,,,,,12.1123,5.395272E-05,-0.001258321,,,21.3623,0.98304,10,0,0.1211216,0.1211216,-2.660055E-06,,,,,,10,-50.5587,-48.43888,142939520,0,,,,,,,,,,,,,,,,
,3701358322.9481,114.285034179688,-0.137559175491333,,,,,,,,,,,,,,,,,,,,,,,12.15324,5.604689E-05,-0.001318921,,,21.3623,0.98304,10,0,0.1215309,0.1215309,-2.797583E-06,,,,,,10,-50.66911,-48.5655,142939520,0,,,,,,,,,,,,,,,,
,3701358397.69366,115.289520263672,-0.132911920547485,,,,,,,,,,,,,,,,,,,,,,,12.19345,6.644209E-05,-0.001259664,,,21.3623,0.98304,10,0,0.1219331,0.1219331,-2.680735E-06,,,,,,10,-50.78305,-48.69246,142939520,0,,,,,,,,,,,,,,,,
,3701358399.46505,115.281112670898,-0.132911920547485,,,,,,,,,,,,,,,,,,,,,,,12.19332,6.02185E-05,-0.001348018,,,21.3623,0.98304,10,0,0.1219318,0.1219318,-2.868731E-06,,,,,,10,-50.78072,-48.69347,142939520,0,,,,,,,,,,,,,,,,
,3701358474.48423,116.286201477051,-0.128264650702477,,,,,,,,,,,,,,,,,,,,,,,12.23328,8.460365E-05,-0.00124064,,,21.3623,0.98304,10,0,0.1223314,0.1223314,-2.648872E-06,,,,,,10,-50.8934,-48.82067,142939520,0,,,,,,,,,,,,,,,,
,3701358549.25115,117.290321350098,-0.132911920547485,,,,,,,,,,,,,,,,,,,,,,,12.2727,4.695277E-05,-0.001312654,,,21.3623,0.98304,10,0,0.1227256,0.1227256,-2.81166E-06,,,,,,10,-51.00608,-48.94852,142939520,0,,,,,,,,,,,,,,,,
,3701358550.98575,117.281768798828,-0.128264650702477,,,,,,,,,,,,,,,,,,,,,,,12.27265,6.465886E-05,-0.001371099,,,21.3623,0.98304,10,0,0.1227251,0.1227251,-2.936836E-06,,,,,,10,-51.00706,-48.95026,142939520,0,,,,,,,,,,,,,,,,
,3701358626.58998,118.279823303223,-0.132911920547485,,,,,,,,,,,,,,,,,,,,,,,12.31152,5.757591E-05,-0.001293293,,,21.3623,0.98304,10,0,0.1231138,0.1231138,-2.778952E-06,,,,,,10,-51.12341,-49.07753,142939520,0,,,,,,,,,,,,,,,,
,3701358701.41092,119.292114257813,-0.118970096111298,,,,,,,,,,,,,,,,,,,,,,,12.35008,0.01049775,-0.001303393,,,21.3623,0.98304,10,0,0.1234993,0.1234993,-2.809425E-06,,,,,,10,-51.23832,-49.20599,142939520,0,,,,,,,,,,,,,,,,
,3701358703.13973,119.281585693359,-0.128264650702477,,,,,,,,,,,,,,,,,,,,,,,12.34998,5.692115E-05,-0.001249648,,,21.3623,0.98304,10,0,0.1234983,0.1234983,-2.693557E-06,,,,,,10,-51.23802,-49.20811,142939520,0,,,,,,,,,,,,,,,,
,3701358778.55111,120.279739379883,-0.132911920547485,,,,,,,,,,,,,,,,,,,,,,,12.38815,4.460543E-05,-0.001280452,,,21.3623,0.98304,10,0,0.1238801,0.1238801,-2.768485E-06,,,,,,10,-51.35358,-49.34269,142939520,0,,,,,,,,,,,,,,,,
,3701358850.75861,119.992225646973,-0.128264650702477,,,,,,,,,,,,,,,,,,,,,,,12.37437,0.0001001959,-0.001255188,,,21.3623,0.98304,10,0,0.1237422,0.1237422,-2.710841E-06,,,,,,10,-51.30135,-49.29215,142939520,0,,,,,,,,,,,,,,,,
,3701358852.46639,119.997200012207,-0.132911920547485,,,,,,,,,,,,,,,,,,,,,,,12.3748,4.944202E-05,-0.001296091,,,21.3623,0.98304,10,0,0.1237465,0.1237465,-2.799278E-06,,,,,,10,-51.30482,-49.29331,142939520,0,,,,,,,,,,,,,,,,
,3701359057.05389,130.012054443359,-0.132911920547485,,,,,,,,,,,,,,,,,,,,,,,12.73733,8.686046E-05,-0.001249648,,,21.3623,0.98304,10,0,0.1273718,0.1273718,-2.77804E-06,,,,,,10,-52.52637,-50.62252,142939520,0,,,,,,,,,,,,,,,,
,3701359255.6113,140.004516601563,-0.128264650702477,,,,,,,,,,,,,,,,,,,,,,,13.08266,9.249226E-05,-0.001271471,,,21.3623,0.98304,10,0,0.1308251,0.1308251,-2.903185E-06,,,,,,10,-53.77872,-51.99599,142939520,0,,,,,,,,,,,,,,,,
,3701359257.33772,140.002578735352,-0.132911920547485,,,,,,,,,,,,,,,,,,,,,,,13.08308,6.297542E-05,-0.001282634,,,21.3623,0.98304,10,0,0.1308293,0.1308293,-2.928768E-06,,,,,,10,-53.78416,-51.99996,142939520,0,,,,,,,,,,,,,,,,
,3701359458.8808,149.999221801758,-0.128264650702477,,,,,,,,,,,,,,,,,,,,,,,13.41092,6.83821E-05,-0.001326167,,,21.3623,0.98304,10,0,0.1341076,0.1341076,-3.104052E-06,,,,,,10,-55.06864,-53.34602,142939520,0,,,,,,,,,,,,,,,,
,3701359658.3761,159.991302490234,-0.128264650702477,,,,,,,,,,,,,,,,,,,,,,,13.7148,7.366605E-05,-0.001253314,,,21.3623,0.98304,10,0,0.1371464,0.1371464,-3.000002E-06,,,,,,10,-56.31089,-54.62452,142939520,0,,,,,,,,,,,,,,,,
,3701359660.10391,159.989242553711,-0.137559175491333,,,,,,,,,,,,,,,,,,,,,,,13.7151,0.008316644,-0.001244333,,,21.3623,0.98304,10,0,0.1371494,0.1371494,-2.978571E-06,,,,,,10,-56.31191,-54.62746,142939520,0,,,,,,,,,,,,,,,,
,3701359860.2819,169.986633300781,-0.132911920547485,,,,,,,,,,,,,,,,,,,,,,,14.00925,9.026432E-05,-0.001281431,,,21.3623,0.98304,10,0,0.1400909,0.1400909,-3.133159E-06,,,,,,10,-57.6281,-55.91719,142939520,0,,,,,,,,,,,,,,,,
,3701360060.58378,179.983444213867,-0.146853730082512,,,,,,,,,,,,,,,,,,,,,,,14.29627,0.0001039008,-0.001314137,,,21.3623,0.98304,10,0,0.142961,0.142961,-3.278955E-06,,,,,,10,-58.9296,-57.16805,142939520,0,,,,,,,,,,,,,,,,
,3701360062.31746,179.981475830078,-0.132911920547485,,,,,,,,,,,,,,,,,,,,,,,14.29654,6.695255E-05,-0.001369029,,,21.3623,0.98304,10,0,0.1429637,0.1429637,-3.415985E-06,,,,,,10,-58.92502,-57.16889,142939520,0,,,,,,,,,,,,,,,,
,3701360264.55994,189.978164672852,-0.128264650702477,,,,,,,,,,,,,,,,,,,,,,,14.57217,6.760818E-05,-0.001258265,,,21.3623,0.98304,10,0,0.14572,0.14572,-3.200139E-06,,,,,,10,-60.12506,-58.41944,142939520,0,,,,,,,,,,,,,,,,
,3701360479.13832,199.974258422852,-0.128264650702477,,,,,,,,,,,,,,,,,,,,,,,14.83569,8.157611E-05,-0.001308849,,,21.3623,0.98304,10,0,0.1483552,0.1483552,-3.388986E-06,,,,,,10,-61.29937,-59.59735,142939520,0,,,,,,,,,,,,,,,,
,3701360480.92448,199.971969604492,-0.123617373406887,,,,,,,,,,,,,,,,,,,,,,,14.83592,4.997636E-05,-0.00127038,,,21.3623,0.98304,10,0,0.1483575,0.1483575,-3.289428E-06,,,,,,10,-61.30481,-59.58904,142939520,0,,,,,,,,,,,,,,,,
,3701360696.10439,209.966827392578,-0.11432284116745,,,,,,,,,,,,,,,,,,,,,,,15.087,5.873475E-05,-0.001298637,,,21.3623,0.98304,10,0,0.1508683,0.1508683,-3.419504E-06,,,,,,10,-62.47529,-60.6908,142939520,0,,,,,,,,,,,,,,,,
,3701360911.14508,219.96403503418,-0.123617373406887,,,,,,,,,,,,,,,,,,,,,,,15.32629,4.851964E-05,-0.001300875,,,21.3623,0.98304,10,0,0.1532611,0.1532611,-3.479726E-06,,,,,,10,-63.685,-61.82872,142939520,0,,,,,,,,,,,,,,,,
,3701360912.90126,219.959533691406,-0.137559175491333,,,,,,,,,,,,,,,,,,,,,,,15.32645,5.052591E-05,-0.001294217,,,21.3623,0.98304,10,0,0.1532627,0.1532627,-3.46195E-06,,,,,,10,-63.67199,-61.82148,142939520,0,,,,,,,,,,,,,,,,
,3701361125.13817,229.957244873047,-0.142206445336342,,,,,,,,,,,,,,,,,,,,,,,15.55278,3.92676E-05,-0.001254544,,,21.3623,0.98304,10,0,0.155526,0.155526,-3.405387E-06,,,,,,10,-64.82278,-62.88564,142939520,0,,,,,,,,,,,,,,,,
,3701361301.87991,239.955505371094,-0.128264650702477,,,,,,,,,,,,,,,,,,,,,,,15.76668,5.544872E-05,-0.00126803,,,21.3623,0.98304,10,0,0.157665,0.157665,-3.48933E-06,,,,,,10,-65.92793,-63.82079,142939520,0,,,,,,,,,,,,,,,,
,3701361303.60822,239.956420898438,-0.128264650702477,,,,,,,,,,,,,,,,,,,,,,,15.76704,6.918583E-05,-0.001279556,,,21.3623,0.98304,10,0,0.1576685,0.1576685,-3.521128E-06,,,,,,10,-65.91026,-63.81765,142939520,0,,,,,,,,,,,,,,,,
,3701361480.66702,249.944961547852,-0.118970096111298,,,,,,,,,,,,,,,,,,,,,,,15.97068,8.685697E-05,-0.001281515,,,21.3623,0.98304,10,0,0.1597049,0.1597049,-3.572065E-06,,,,,,10,-66.92088,-64.84278,142939520,0,,,,,,,,,,,,,,,,
,3701361552.71096,249.893585205078,-0.11432284116745,,,,,,,,,,,,,,,,,,,,,,,15.97333,3.648404E-05,-0.001303869,,,21.3623,0.98304,10,0,0.1597314,0.1597314,-3.634977E-06,,,,,,10,-66.93581,-64.8559,142939520,0,,,,,,,,,,,,,,,,
,3701361554.43785,249.895614624023,-0.132911920547485,,,,,,,,,,,,,,,,,,,,,,,15.97345,6.726901E-05,-0.001298246,,,21.3623,0.98304,10,0,0.1597326,0.1597326,-3.619327E-06,,,,,,10,-66.95127,-64.86636,142939520,0,,,,,,,,,,,,,,,,
,3701361739.6522,269.782287597656,-0.118970096111298,,,,,,,,,,,,,,,,,,,,,,,16.31816,0.0001209139,-0.00134217,,,21.3623,0.98304,10,0,0.1631797,0.1631797,-3.822532E-06,,,,,,10,-69.02901,-66.78861,142939520,0,,,,,,,,,,,,,,,,
,3701361914.28293,279.916809082031,-0.128264650702477,,,,,,,,,,,,,,,,,,,,,,,16.48435,8.363255E-05,-0.001325188,,,21.3623,0.98304,10,0,0.1648415,0.1648415,-3.812602E-06,,,,,,10,-70.26614,-67.7591,142939520,0,,,,,,,,,,,,,,,,
,3701361916.02795,279.915985107422,-0.128264650702477,,,,,,,,,,,,,,,,,,,,,,,16.4845,4.572735E-05,-0.001285572,,,21.3623,0.98304,10,0,0.1648431,0.1648431,-3.69866E-06,,,,,,10,-70.27365,-67.73916,142939520,0,,,,,,,,,,,,,,,,
,3701362050.37567,289.760986328125,-0.11432284116745,,,,,,,,,,,,,,,,,,,,,,,16.62396,5.224282E-05,-0.001306695,,,21.3623,0.98304,10,0,0.1662376,0.1662376,-3.791236E-06,,,,,,10,-71.63472,-68.92352,142939520,0,,,,,,,,,,,,,,,,
,3701362185.81346,299.76123046875,-0.132911920547485,,,,,,,,,,,,,,,,,,,,,,,16.75603,0.0001424873,-0.001281207,,,21.3623,0.98304,10,0,0.1675584,0.1675584,-3.746821E-06,,,,,,10,-73.00444,-69.99375,142939520,0,,,,,,,,,,,,,,,,
,3701362187.53514,299.775939941406,-0.137559175491333,,,,,,,,,,,,,,,,,,,,,,,16.75632,5.953837E-05,-0.001340911,,,21.3623,0.98304,10,0,0.1675612,0.1675612,-3.921489E-06,,,,,,10,-72.99183,-69.9569,142939520,0,,,,,,,,,,,,,,,,
,3701362321.86502,310.010925292969,-0.132911920547485,,,,,,,,,,,,,,,,,,,,,,,16.88439,9.254567E-05,-0.001296847,,,21.3623,0.98304,10,0,0.1688419,0.1688419,-3.821609E-06,,,,,,10,-74.48966,-71.11243,142939520,0,,,,,,,,,,,,,,,,
,3701362500.18501,319.916412353516,-0.137559175491333,,,,,,,,,,,,,,,,,,,,,,,16.98811,6.132097E-05,-0.001348186,,,21.3623,0.98304,10,0,0.1698791,0.1698791,-3.997302E-06,,,,,,10,-76.11869,-72.19346,142939520,0,,,,,,,,,,,,,,,,
,3701362501.97656,319.913818359375,-0.128264650702477,,,,,,,,,,,,,,,,,,,,,,,16.98821,4.718956E-05,-0.001360859,,,21.3623,0.98304,10,0,0.1698801,0.1698801,-4.034903E-06,,,,,,10,-76.05757,-72.19314,142939520,0,,,,,,,,,,,,,,,,